<?xml version="1.0"?>
<robot xmlns:xacro="http://ros.org/wiki/xacro" name="jaguar_wheel">

  <!--<xacro:property name="M_PI" default="3.14159"/>
  <xacro:property name="wheel_length" default="0.09" />
  <xacro:property name="wheel_radius" default="0.13" />-->

  <xacro:macro name="jaguar_wheel" params="wheel_prefix parent_link *joint_origin">
    <gazebo reference="${wheel_prefix}_wheel_link">
      <material>Gazebo/Black</material>
    </gazebo>
		<link name="${wheel_prefix}_wheel_link">
			<inertial>
				<mass value="2.637" />
				<origin xyz="0 0 0" />
				<inertia  ixx="0.02467" ixy="0" ixz="0" iyy="0.02467" iyz="0" izz="0.04411" />
			</inertial>
			<visual>
				<origin xyz="0 0 0" rpy="${M_PI/2}  0 0" />
				<geometry>
          <cylinder length="${wheel_length}" radius="${wheel_radius}"/>
				</geometry>
        <material name="black">
          <color rgba="0 0 0 1"/>
        </material>
			</visual>
			<collision>
				<origin xyz="0 0 0" rpy="${M_PI/2} 0 0" />
				<geometry>
					<cylinder length="${wheel_length}" radius="${wheel_radius}" />
				</geometry>
			</collision>
		</link>

		<gazebo reference="${wheel_prefix}_wheel_link">
			<mu1 value="1.0"/>
			<mu2 value="1.0"/>
			<kp value="10000000.0" />
			<kd value="1.0" />
			<fdir1 value="1 0 0"/>
		</gazebo>

		<joint name="${wheel_prefix}_wheel" type="continuous">
      <parent link="${parent_link}"/>
			<child link="${wheel_prefix}_wheel_link"/>
      <xacro:insert_block name="joint_origin"/>
			<axis xyz="0 1 0" rpy="0 0 0" />
		</joint>

		<transmission name="${wheel_prefix}_wheel_trans" type="SimpleTransmission">
			<type>transmission_interface/SimpleTransmission</type>
			<actuator name="${wheel_prefix}_wheel_motor">
				<mechanicalReduction>1</mechanicalReduction>
			</actuator>
			<joint name="${wheel_prefix}_wheel">
				<hardwareInterface>VelocityJointInterface</hardwareInterface>
			</joint>
		</transmission>

	</xacro:macro>
</robot>
